<?xml version="1.0" ?>
<!-- =================================================================================== -->
<!-- |    This document was autogenerated by xacro from anymal.urdf.xacro              | -->
<!-- |    EDITING THIS FILE BY HAND IS NOT RECOMMENDED                                 | -->
<!-- =================================================================================== -->
<!-- This file contains the description of the ANYmal Bedi robot. -->
<robot name="anymal" xmlns:xacro="http://www.ros.org/wiki/xacro">
  <material name="black">
    <color rgba="0.0 0.0 0.0 1.0"/>
  </material>
  <material name="blue">
    <color rgba="0.0 0.0 0.8 1.0"/>
  </material>
  <material name="green">
    <color rgba="0.0 0.8 0.0 1.0"/>
  </material>
  <material name="grey">
    <color rgba="0.2 0.2 0.2 1.0"/>
  </material>
  <material name="light_grey">
    <color rgba="0.4 0.4 0.4 1.0"/>
  </material>
  <material name="orange">
    <color rgba="1.0 0.423529411765 0.0392156862745 1.0"/>
  </material>
  <material name="brown">
    <color rgba="0.870588235294 0.811764705882 0.764705882353 1.0"/>
  </material>
  <material name="red">
    <color rgba="0.8 0.0 0.0 1.0"/>
  </material>
  <material name="white">
    <color rgba="1.0 1.0 1.0 1.0"/>
  </material>
  <!-- Material for the visual primitives -->
  <material name="anymal_material">
    <color rgba="0.7 0.7 0.7 1.0"/>
  </material>
  <!-- Xacro:Properties -->
  <!-- [m] -->
  <!-- Base link -->
  <link name="base">
    <visual>
      <origin rpy="0 0 0" xyz="0 0 0"/>
      <geometry>
        <mesh filename="./base/2_0_b/anymal_base.dae" scale="0.001 0.001     0.001"/>
      </geometry>
      <material name="anymal_material"/>
    </visual>
    <collision>
      <!-- Main Body -->
      <origin rpy="0 0 0" xyz="0 0 0.08"/>
      <geometry>
        <box size="0.531 0.27 0.24"/>
      </geometry>
    </collision>
    <collision>
      <!-- HAA actuators -->
      <origin rpy="0 1.57079632679 0" xyz="0.227 0.116 0"/>
      <geometry>
        <cylinder length="0.1" radius="0.05"/>
      </geometry>
    </collision>
    <collision>
      <origin rpy="0 1.57079632679 0" xyz="0.227 -0.116 0"/>
      <geometry>
        <cylinder length="0.1" radius="0.05"/>
      </geometry>
    </collision>
    <collision>
      <origin rpy="0 1.57079632679 0" xyz="-0.227 0.116 0"/>
      <geometry>
        <cylinder length="0.1" radius="0.05"/>
      </geometry>
    </collision>
    <collision>
      <origin rpy="0 1.57079632679 0" xyz="-0.227 -0.116 0"/>
      <geometry>
        <cylinder length="0.1" radius="0.05"/>
      </geometry>
    </collision>
    <collision>
      <!-- Belly plate front bump -->
      <origin rpy="0 0 0" xyz="0.2155 0.0 -0.09"/>
      <geometry>
        <box size="0.1 0.1 0.07"/>
      </geometry>
    </collision>
    <collision>
      <!-- Belly plate hind bump-->
      <origin rpy="0 0 0" xyz="-0.2155 0.0 -0.09"/>
      <geometry>
        <box size="0.1 0.1 0.07"/>
      </geometry>
    </collision>
    <collision>
      <!-- Belly plate middle bump-->
      <origin rpy="0 0 0" xyz="0 0 -0.09"/>
      <geometry>
        <box size="0.531 0.02 0.07"/>
      </geometry>
    </collision>
    <inertial>
      <mass value="0.0001"/>
      <inertia ixx="0.0" ixy="0.0" ixz="0.0" iyy="0.0" iyz="0.0" izz="0.0"/>
    </inertial>
  </link>
  <!-- Fixed joint to add dummy inertia link -->
  <joint name="base_to_base_inertia" type="fixed">
    <parent link="base"/>
    <child link="base_inertia"/>
    <origin rpy="0 0 0" xyz="0 0 0"/>
  </joint>
  <!-- Dummy inertia link, because KDL cannot have inertia on the base link -->
  <link name="base_inertia">
    <inertial>
      <origin rpy="0 0 0" xyz="0.001712029101 -0.001380403461 0.053974184671"/>
      <mass value="19.642"/>
      <inertia ixx="0.248057547487" ixy="0.00109783880089" ixz="-0.00394501164854" iyy="0.650151658461" iyz="-0.00213569105487" izz="0.620944203624"/>
    </inertial>
  </link>
  <!-- Xacro:Properties -->
  <!-- [kg * m^2] -->
  <!-- [Nm] -->
  <link name="LF_HIP">
    <visual>
      <origin rpy="0 0 0.0" xyz="0 0 0"/>
      <geometry>
        <mesh filename="./hip/3_0/anymal_hip_l.dae" scale="0.001 0.001     0.001"/>
      </geometry>
      <material name="anymal_material"/>
    </visual>
    <collision>
      <!-- Protector -->
      <origin rpy="1.57079632679 0 0" xyz="0.0635 -0.009 0.0"/>
      <geometry>
        <cylinder length="0.1" radius="0.08"/>
      </geometry>
    </collision>
    <collision>
      <!-- Heatfins -->
      <origin rpy="1.57079632679 0 0" xyz="0.0635 -0.074 0.0"/>
      <geometry>
        <cylinder length="0.03" radius="0.045"/>
      </geometry>
    </collision>
    <inertial>
      <origin rpy="0 0 0" xyz="0.0642 -0.0102 0.0033"/>
      <mass value="1.516"/>
      <inertia ixx="0.002318" ixy="-1e-06" ixz="9e-06" iyy="0.00206" iyz="0.000333" izz="0.002439"/>
    </inertial>
  </link>
  <!-- Hip joint -->
  <joint name="LF_HAA" type="revolute">
    <parent link="base"/>
    <child link="LF_HIP"/>
    <origin xyz="0.277 0.116 0.0"/>
    <axis xyz="1 0 0"/>
    <limit effort="80" lower="-6.28" upper="6.28" velocity="15"/>
    <dynamics damping="0.0" friction="0.0"/>
  </joint>
  <!-- Xacro:Properties -->
  <!-- [m] -->
  <!-- [Nm] -->
  <link name="LF_THIGH">
    <visual>
      <origin rpy="0 0 0.0" xyz="0 0 0"/>
      <geometry>
        <mesh filename="./thigh/3_0/anymal_thigh_l.dae" scale="0.001 0.001     0.001"/>
      </geometry>
      <material name="anymal_material"/>
    </visual>
    <collision>
      <!-- thigh with heat fins -->
      <origin rpy="0.145 0 0" xyz="0 0.035 -0.125"/>
      <geometry>
        <box size="0.08 0.04 -0.25"/>
      </geometry>
    </collision>
    <collision>
      <!-- KFE actuator -->
      <origin rpy="1.57079632679 0 0" xyz="0.0 0.069 -0.25"/>
      <geometry>
        <cylinder length="0.12" radius="0.06"/>
      </geometry>
    </collision>
    <collision>
      <!-- upper protector -->
      <origin rpy="1.71579632679 0 0" xyz="0 -0.005 0"/>
      <geometry>
        <cylinder length="0.12" radius="0.066"/>
      </geometry>
    </collision>
    <inertial>
      <origin rpy="0 0 0" xyz="-0.0001 0.0513 -0.208"/>
      <mass value="1.765"/>
      <inertia ixx="0.013479" ixy="-3e-06" ixz="3.8e-05" iyy="0.01325" iyz="-0.001623" izz="0.002229"/>
    </inertial>
  </link>
  <!-- Thigh joint -->
  <joint name="LF_HFE" type="revolute">
    <parent link="LF_HIP"/>
    <child link="LF_THIGH"/>
    <origin xyz="0.0635                    0.041                    0.0"/>
    <axis xyz="0 1 0"/>
    <limit effort="80" lower="-6.28" upper="6.28" velocity="15"/>
    <dynamics damping="0.0" friction="0.0"/>
  </joint>
  <!-- Xacro:Properties -->
  <!-- [m] -->
  <!-- [Nm] -->
  <link name="LF_SHANK">
    <visual>
      <origin rpy="0 0 0.0" xyz="0 0 0"/>
      <geometry>
        <mesh filename="./shank/3_0/anymal_shank_l.dae" scale="0.001 0.001     0.001"/>
      </geometry>
      <material name="anymal_material"/>
    </visual>
    <collision>
      <origin rpy="0 1.57079632679 0" xyz="0.065 -0.015 0.01"/>
      <geometry>
        <box size="0.08 0.07 0.13"/>
      </geometry>
    </collision>
    <inertial>
      <origin rpy="0 0 0" xyz="0.029 -0.004 0.001"/>
      <mass value="0.21"/>
      <inertia ixx="0.0037693717909" ixy="-7.7334500762e-05" ixz="-0.000152069372983" iyy="0.00400446467635" iyz="-0.0003218356083" izz="0.000418471691904"/>
    </inertial>
  </link>
  <!-- Shank joint -->
  <joint name="LF_KFE" type="revolute">
    <parent link="LF_THIGH"/>
    <child link="LF_SHANK"/>
    <origin xyz="0.0 0.109 -0.25"/>
    <axis xyz="0 1 0"/>
    <limit effort="80" lower="-6.28" upper="6.28" velocity="15"/>
    <dynamics damping="0.0" friction="0.0"/>
  </joint>
  <!-- Xacro:Properties -->
  <!-- [m] -->
  <!-- Foot adapter link -->
  <link name="LF_ADAPTER">
    <visual>
      <origin rpy="0 0 0.0" xyz="0 0 0"/>
      <geometry>
        <mesh filename="./adapter/3_0/anymal_adapter.dae" scale="0.001 0.001     0.001"/>
      </geometry>
      <material name="anymal_material"/>
    </visual>
    <collision>
      <origin rpy="0 0 0" xyz="0 0 -0.114"/>
      <geometry>
        <cylinder length="-0.228" radius="0.015"/>
      </geometry>
    </collision>
    <inertial>
      <origin rpy="0 0 0" xyz="0.0 0.0036 -0.18036"/>
      <mass value="0.261"/>
      <inertia ixx="0.002983" ixy="3e-08" ixz="-3.2e-07" iyy="0.00298" iyz="-7e-05" izz="8.4e-05"/>
    </inertial>
  </link>
  <!-- Foot adapter joint ankle -->
  <joint name="LF_ADAPTER_JOINT" type="fixed">
    <parent link="LF_SHANK"/>
    <child link="LF_ADAPTER"/>
    <origin rpy="0.0 0.0 0.0" xyz="0.1 -0.02 0.0"/>
  </joint>
  <!-- Xacro:Properties -->
  <!-- [m] -->
  <link name="LF_MOUNT">
    <inertial>
      <mass value="0.0001"/>
      <inertia ixx="0.0" ixy="0.0" ixz="0.0" iyy="0.0" iyz="0.0" izz="0.0"/>
    </inertial>
  </link>
  <!-- Foot adapter joint ankle -->
  <joint name="LF_MOUNT_JOINT" type="fixed">
    <parent link="LF_ADAPTER"/>
    <child link="LF_MOUNT"/>
    <origin rpy="0.226893 0.0 0.0" xyz="0.0 0.0 -0.228"/>
  </joint>
  <!-- Foot link -->
  <link name="LF_FOOT">
    <visual>
      <origin rpy="0 0 0.0" xyz="0 0 0.0519"/>
      <geometry>
        <mesh filename="./foot/8_0/anymal_foot_l.dae" scale="0.001 0.001     0.001"/>
      </geometry>
      <material name="anymal_material"/>
    </visual>
    <collision>
      <origin xyz="0 0 0.017275"/>
      <geometry>
        <sphere radius="0.034625"/>
      </geometry>
    </collision>  
    <inertial>
      <mass value="0.0001"/>
      <inertia ixx="0.0" ixy="0.0" ixz="0.0" iyy="0.0" iyz="0.0" izz="0.0"/>
    </inertial>
  </link>
  <!-- Gazebo customization -->
  <gazebo reference="LF_FOOT">
    <kp>1000000.0</kp>
    <kd>100.0</kd>
    <mu1>0.8</mu1>
    <mu2>0.8</mu2>
  </gazebo>
  <!-- Foot joint -->
  <joint name="LF_MOUNT_TO_FOOT" type="fixed">
    <parent link="LF_MOUNT"/>
    <child link="LF_FOOT"/>
    <origin rpy="0.0 0.0 0.0" xyz="0.0 0.0 -0.0519"/>
    <material name="anymal_material"/>
  </joint>
  <!-- Xacro:Properties -->
  <!-- [kg * m^2] -->
  <!-- [Nm] -->
  <link name="RF_HIP">
    <visual>
      <origin rpy="0 0 0.0" xyz="0 0 0"/>
      <geometry>
        <mesh filename="./hip/3_0/anymal_hip_r.dae" scale="0.001 0.001     0.001"/>
      </geometry>
      <material name="anymal_material"/>
    </visual>
    <collision>
      <!-- Protector -->
      <origin rpy="1.57079632679 0 0" xyz="0.0635 0.009 0.0"/>
      <geometry>
        <cylinder length="0.1" radius="0.08"/>
      </geometry>
    </collision>
    <collision>
      <!-- Heatfins -->
      <origin rpy="1.57079632679 0 0" xyz="0.0635 0.074 0.0"/>
      <geometry>
        <cylinder length="0.03" radius="0.045"/>
      </geometry>
    </collision>
    <inertial>
      <origin rpy="0 0 0" xyz="0.0642 0.0102 0.0033"/>
      <mass value="1.516"/>
      <inertia ixx="0.002318" ixy="1e-06" ixz="9e-06" iyy="0.00206" iyz="-0.000333" izz="0.002439"/>
    </inertial>
  </link>
  <!-- Hip joint -->
  <joint name="RF_HAA" type="revolute">
    <parent link="base"/>
    <child link="RF_HIP"/>
    <origin xyz="0.277 -0.116 0.0"/>
    <axis xyz="1 0 0"/>
    <limit effort="80" lower="-6.28" upper="6.28" velocity="15"/>
    <dynamics damping="0.0" friction="0.0"/>
  </joint>
  <!-- Xacro:Properties -->
  <!-- [m] -->
  <!-- [Nm] -->
  <link name="RF_THIGH">
    <visual>
      <origin rpy="0 0 0.0" xyz="0 0 0"/>
      <geometry>
        <mesh filename="./thigh/3_0/anymal_thigh_r.dae" scale="0.001 0.001     0.001"/>
      </geometry>
      <material name="anymal_material"/>
    </visual>
    <collision>
      <!-- thigh with heat fins -->
      <origin rpy="-0.145 0 0" xyz="0 -0.035 -0.125"/>
      <geometry>
        <box size="0.08 0.04 -0.25"/>
      </geometry>
    </collision>
    <collision>
      <!-- KFE actuator -->
      <origin rpy="1.57079632679 0 0" xyz="0.0 -0.069 -0.25"/>
      <geometry>
        <cylinder length="0.12" radius="0.06"/>
      </geometry>
    </collision>
    <collision>
      <!-- upper protector -->
      <origin rpy="-1.71579632679 0 0" xyz="0 0.005 0"/>
      <geometry>
        <cylinder length="0.12" radius="0.066"/>
      </geometry>
    </collision>
    <inertial>
      <origin rpy="0 0 0" xyz="-0.0001 -0.0513 -0.208"/>
      <mass value="1.765"/>
      <inertia ixx="0.013479" ixy="3e-06" ixz="3.8e-05" iyy="0.01325" iyz="0.001623" izz="0.002229"/>
    </inertial>
  </link>
  <!-- Thigh joint -->
  <joint name="RF_HFE" type="revolute">
    <parent link="RF_HIP"/>
    <child link="RF_THIGH"/>
    <origin xyz="0.0635                    -0.041                    0.0"/>
    <axis xyz="0 1 0"/>
    <limit effort="80" lower="-6.28" upper="6.28" velocity="15"/>
    <dynamics damping="0.0" friction="0.0"/>
  </joint>
  <!-- Xacro:Properties -->
  <!-- [m] -->
  <!-- [Nm] -->
  <link name="RF_SHANK">
    <visual>
      <origin rpy="0 0 0.0" xyz="0 0 0"/>
      <geometry>
        <mesh filename="./shank/3_0/anymal_shank_r.dae" scale="0.001 0.001     0.001"/>
      </geometry>
      <material name="anymal_material"/>
    </visual>
    <collision>
      <origin rpy="0 1.57079632679 0" xyz="0.065 0.015 0.01"/>
      <geometry>
        <box size="0.08 0.07 0.13"/>
      </geometry>
    </collision>
    <inertial>
      <origin rpy="0 0 0" xyz="0.029 0.004 0.001"/>
      <mass value="0.21"/>
      <inertia ixx="0.0037693717909" ixy="7.7334500762e-05" ixz="-0.000152069372983" iyy="0.00400446467635" iyz="0.0003218356083" izz="0.000418471691904"/>
    </inertial>
  </link>
  <!-- Shank joint -->
  <joint name="RF_KFE" type="revolute">
    <parent link="RF_THIGH"/>
    <child link="RF_SHANK"/>
    <origin xyz="0.0 -0.109 -0.25"/>
    <axis xyz="0 1 0"/>
    <limit effort="80" lower="-6.28" upper="6.28" velocity="15"/>
    <dynamics damping="0.0" friction="0.0"/>
  </joint>
  <!-- Xacro:Properties -->
  <!-- [m] -->
  <!-- Foot adapter link -->
  <link name="RF_ADAPTER">
    <visual>
      <origin rpy="0 0 0.0" xyz="0 0 0"/>
      <geometry>
        <mesh filename="./adapter/3_0/anymal_adapter.dae" scale="0.001 0.001     0.001"/>
      </geometry>
      <material name="anymal_material"/>
    </visual>
    <collision>
      <origin rpy="0 0 0" xyz="0 0 -0.114"/>
      <geometry>
        <cylinder length="-0.228" radius="0.015"/>
      </geometry>
    </collision>
    <inertial>
      <origin rpy="0 0 0" xyz="0.0 -0.0036 -0.18036"/>
      <mass value="0.261"/>
      <inertia ixx="0.002983" ixy="-3e-08" ixz="-3.2e-07" iyy="0.00298" iyz="7e-05" izz="8.4e-05"/>
    </inertial>
  </link>
  <!-- Foot adapter joint ankle -->
  <joint name="RF_ADAPTER_JOINT" type="fixed">
    <parent link="RF_SHANK"/>
    <child link="RF_ADAPTER"/>
    <origin rpy="-0.0 0.0 -0.0" xyz="0.1 0.02 0.0"/>
  </joint>
  <!-- Xacro:Properties -->
  <!-- [m] -->
  <link name="RF_MOUNT">
    <inertial>
      <mass value="0.001"/>
      <inertia ixx="0.0" ixy="0.0" ixz="0.0" iyy="0.0" iyz="0.0" izz="0.0"/>
    </inertial>
    </link>
  <!-- Foot adapter joint ankle -->
  <joint name="RF_MOUNT_JOINT" type="fixed">
    <parent link="RF_ADAPTER"/>
    <child link="RF_MOUNT"/>
    <origin rpy="-0.226893 0.0 0.0" xyz="0.0 -0.0 -0.228"/>
  </joint>
  <!-- Foot link -->
  <link name="RF_FOOT">
    <visual>
      <origin rpy="0 0 0.0" xyz="0 0 0.0519"/>
      <geometry>
        <mesh filename="./foot/8_0/anymal_foot_r.dae" scale="0.001 0.001     0.001"/>
      </geometry>
      <material name="anymal_material"/>
    </visual>
    <collision>
      <origin xyz="0 0 0.017275"/>
      <geometry>
        <sphere radius="0.034625"/>
      </geometry>
    </collision>
    <inertial>
      <mass value="0.001"/>
      <inertia ixx="0.0" ixy="0.0" ixz="0.0" iyy="0.0" iyz="0.0" izz="0.0"/>
    </inertial>
  </link>
  <!-- Gazebo customization -->
  <gazebo reference="RF_FOOT">
    <kp>1000000.0</kp>
    <kd>100.0</kd>
    <mu1>0.8</mu1>
    <mu2>0.8</mu2>
  </gazebo>
  <!-- Foot joint -->
  <joint name="RF_MOUNT_TO_FOOT" type="fixed">
    <parent link="RF_MOUNT"/>
    <child link="RF_FOOT"/>
    <origin rpy="-0.0 0.0 0.0" xyz="0.0 0.0 -0.0519"/>
    <material name="anymal_material"/>
  </joint>
  <!-- Xacro:Properties -->
  <!-- [kg * m^2] -->
  <!-- [Nm] -->
  <link name="LH_HIP">
    <visual>
      <origin rpy="0 0 -3.14159265359" xyz="0 0 0"/>
      <geometry>
        <mesh filename="./hip/3_0/anymal_hip_r.dae" scale="0.001 0.001     0.001"/>
      </geometry>
      <material name="anymal_material"/>
    </visual>
    <collision>
      <!-- Protector -->
      <origin rpy="-1.57079632679 0 0" xyz="-0.0635 -0.009 0.0"/>
      <geometry>
        <cylinder length="0.1" radius="0.08"/>
      </geometry>
    </collision>
    <collision>
      <!-- Heatfins -->
      <origin rpy="-1.57079632679 0 0" xyz="-0.0635 -0.074 0.0"/>
      <geometry>
        <cylinder length="0.03" radius="0.045"/>
      </geometry>
    </collision>
    <inertial>
      <origin rpy="0 0 0" xyz="-0.0642 -0.0102 0.0033"/>
      <mass value="1.516"/>
      <inertia ixx="0.002318" ixy="1e-06" ixz="-9e-06" iyy="0.00206" iyz="0.000333" izz="0.002439"/>
    </inertial>
  </link>
  <!-- Hip joint -->
  <joint name="LH_HAA" type="revolute">
    <parent link="base"/>
    <child link="LH_HIP"/>
    <origin xyz="-0.277 0.116 0.0"/>
    <axis xyz="1 0 0"/>
    <limit effort="80" lower="-6.28" upper="6.28" velocity="15"/>
    <dynamics damping="0.0" friction="0.0"/>
  </joint>
  <!-- Xacro:Properties -->
  <!-- [m] -->
  <!-- [Nm] -->
  <link name="LH_THIGH">
    <visual>
      <origin rpy="0 0 -3.14159265359" xyz="0 0 0"/>
      <geometry>
        <mesh filename="./thigh/3_0/anymal_thigh_r.dae" scale="0.001 0.001     0.001"/>
      </geometry>
      <material name="anymal_material"/>
    </visual>
    <collision>
      <!-- thigh with heat fins -->
      <origin rpy="0.145 0 0" xyz="0 0.035 -0.125"/>
      <geometry>
        <box size="0.08 0.04 -0.25"/>
      </geometry>
    </collision>
    <collision>
      <!-- KFE actuator -->
      <origin rpy="1.57079632679 0 0" xyz="0.0 0.069 -0.25"/>
      <geometry>
        <cylinder length="0.12" radius="0.06"/>
      </geometry>
    </collision>
    <collision>
      <!-- upper protector -->
      <origin rpy="1.71579632679 0 0" xyz="0 -0.005 0"/>
      <geometry>
        <cylinder length="0.12" radius="0.066"/>
      </geometry>
    </collision>
    <inertial>
      <origin rpy="0 0 0" xyz="0.0001 0.0513 -0.208"/>
      <mass value="1.765"/>
      <inertia ixx="0.013479" ixy="3e-06" ixz="-3.8e-05" iyy="0.01325" iyz="-0.001623" izz="0.002229"/>
    </inertial>
  </link>
  <!-- Thigh joint -->
  <joint name="LH_HFE" type="revolute">
    <parent link="LH_HIP"/>
    <child link="LH_THIGH"/>
    <origin xyz="-0.0635                    0.041                    0.0"/>
    <axis xyz="0 1 0"/>
    <limit effort="80" lower="-6.28" upper="6.28" velocity="15"/>
    <dynamics damping="0.0" friction="0.0"/>
  </joint>
  <!-- Xacro:Properties -->
  <!-- [m] -->
  <!-- [Nm] -->
  <link name="LH_SHANK">
    <visual>
      <origin rpy="0 0 -3.14159265359" xyz="0 0 0"/>
      <geometry>
        <mesh filename="./shank/3_0/anymal_shank_r.dae" scale="0.001 0.001     0.001"/>
      </geometry>
      <material name="anymal_material"/>
    </visual>
    <collision>
      <origin rpy="0 1.57079632679 0" xyz="-0.065 -0.015 0.01"/>
      <geometry>
        <box size="0.08 0.07 0.13"/>
      </geometry>
    </collision>
    <inertial>
      <origin rpy="0 0 0" xyz="-0.029 -0.004 0.001"/>
      <mass value="0.21"/>
      <inertia ixx="0.0037693717909" ixy="7.7334500762e-05" ixz="0.000152069372983" iyy="0.00400446467635" iyz="-0.0003218356083" izz="0.000418471691904"/>
    </inertial>
  </link>
  <!-- Shank joint -->
  <joint name="LH_KFE" type="revolute">
    <parent link="LH_THIGH"/>
    <child link="LH_SHANK"/>
    <origin xyz="-0.0 0.109 -0.25"/>
    <axis xyz="0 1 0"/>
    <limit effort="80" lower="-6.28" upper="6.28" velocity="15"/>
    <dynamics damping="0.0" friction="0.0"/>
  </joint>
  <!-- Xacro:Properties -->
  <!-- [m] -->
  <!-- Foot adapter link -->
  <link name="LH_ADAPTER">
    <visual>
      <origin rpy="0 0 -3.14159265359" xyz="0 0 0"/>
      <geometry>
        <mesh filename="./adapter/3_0/anymal_adapter.dae" scale="0.001 0.001     0.001"/>
      </geometry>
      <material name="anymal_material"/>
    </visual>
    <collision>
      <origin rpy="0 0 0" xyz="0 0 -0.114"/>
      <geometry>
        <cylinder length="-0.228" radius="0.015"/>
      </geometry>
    </collision>
    <inertial>
      <origin rpy="0 0 0" xyz="-0.0 0.0036 -0.18036"/>
      <mass value="0.261"/>
      <inertia ixx="0.002983" ixy="-3e-08" ixz="3.2e-07" iyy="0.00298" iyz="-7e-05" izz="8.4e-05"/>
    </inertial>
  </link>
  <!-- Foot adapter joint ankle -->
  <joint name="LH_ADAPTER_JOINT" type="fixed">
    <parent link="LH_SHANK"/>
    <child link="LH_ADAPTER"/>
    <origin rpy="0.0 -0.0 -0.0" xyz="-0.1 -0.02 0.0"/>
  </joint>
  <!-- Xacro:Properties -->
  <!-- [m] -->
  <link name="LH_MOUNT">
    <inertial>
      <mass value="0.0001"/>
      <inertia ixx="0.0" ixy="0.0" ixz="0.0" iyy="0.0" iyz="0.0" izz="0.0"/>
    </inertial>
    </link>
  <!-- Foot adapter joint ankle -->
  <joint name="LH_MOUNT_JOINT" type="fixed">
    <parent link="LH_ADAPTER"/>
    <child link="LH_MOUNT"/>
    <origin rpy="0.226893 -0.0 -0.0" xyz="-0.0 0.0 -0.228"/>
  </joint>
  <!-- Foot link -->
  <link name="LH_FOOT">
    <visual>
      <origin rpy="0 0 -3.14159265359" xyz="0 0 0.0519"/>
      <geometry>
        <mesh filename="./foot/8_0/anymal_foot_r.dae" scale="0.001 0.001     0.001"/>
      </geometry>
      <material name="anymal_material"/>
    </visual>
    <collision>
      <origin xyz="0 0 0.017275"/>
      <geometry>
        <sphere radius="0.034625"/>
      </geometry>
    </collision>
    <inertial>
      <mass value="0.0001"/>
      <inertia ixx="0.0" ixy="0.0" ixz="0.0" iyy="0.0" iyz="0.0" izz="0.0"/>
    </inertial>
  </link>
  <!-- Gazebo customization -->
  <gazebo reference="LH_FOOT">
    <kp>1000000.0</kp>
    <kd>100.0</kd>
    <mu1>0.8</mu1>
    <mu2>0.8</mu2>
  </gazebo>
  <!-- Foot joint -->
  <joint name="LH_MOUNT_TO_FOOT" type="fixed">
    <parent link="LH_MOUNT"/>
    <child link="LH_FOOT"/>
    <origin rpy="0.0 -0.0 -0.0" xyz="0.0 0.0 -0.0519"/>
    <material name="anymal_material"/>
  </joint>
  <!-- Xacro:Properties -->
  <!-- [kg * m^2] -->
  <!-- [Nm] -->
  <link name="RH_HIP">
    <visual>
      <origin rpy="0 0 -3.14159265359" xyz="0 0 0"/>
      <geometry>
        <mesh filename="./hip/3_0/anymal_hip_l.dae" scale="0.001 0.001     0.001"/>
      </geometry>
      <material name="anymal_material"/>
    </visual>
    <collision>
      <!-- Protector -->
      <origin rpy="-1.57079632679 0 0" xyz="-0.0635 0.009 0.0"/>
      <geometry>
        <cylinder length="0.1" radius="0.08"/>
      </geometry>
    </collision>
    <collision>
      <!-- Heatfins -->
      <origin rpy="-1.57079632679 0 0" xyz="-0.0635 0.074 0.0"/>
      <geometry>
        <cylinder length="0.03" radius="0.045"/>
      </geometry>
    </collision>
    <inertial>
      <origin rpy="0 0 0" xyz="-0.0642 0.0102 0.0033"/>
      <mass value="1.516"/>
      <inertia ixx="0.002318" ixy="-1e-06" ixz="-9e-06" iyy="0.00206" iyz="-0.000333" izz="0.002439"/>
    </inertial>
  </link>
  <!-- Hip joint -->
  <joint name="RH_HAA" type="revolute">
    <parent link="base"/>
    <child link="RH_HIP"/>
    <origin xyz="-0.277 -0.116 0.0"/>
    <axis xyz="1 0 0"/>
    <limit effort="80" lower="-6.28" upper="6.28" velocity="15"/>
    <dynamics damping="0.0" friction="0.0"/>
  </joint>
  <!-- Xacro:Properties -->
  <!-- [m] -->
  <!-- [Nm] -->
  <link name="RH_THIGH">
    <visual>
      <origin rpy="0 0 -3.14159265359" xyz="0 0 0"/>
      <geometry>
        <mesh filename="./thigh/3_0/anymal_thigh_l.dae" scale="0.001 0.001     0.001"/>
      </geometry>
      <material name="anymal_material"/>
    </visual>
    <collision>
      <!-- thigh with heat fins -->
      <origin rpy="-0.145 0 0" xyz="0 -0.035 -0.125"/>
      <geometry>
        <box size="0.08 0.04 -0.25"/>
      </geometry>
    </collision>
    <collision>
      <!-- KFE actuator -->
      <origin rpy="1.57079632679 0 0" xyz="0.0 -0.069 -0.25"/>
      <geometry>
        <cylinder length="0.12" radius="0.06"/>
      </geometry>
    </collision>
    <collision>
      <!-- upper protector -->
      <origin rpy="-1.71579632679 0 0" xyz="0 0.005 0"/>
      <geometry>
        <cylinder length="0.12" radius="0.066"/>
      </geometry>
    </collision>
    <inertial>
      <origin rpy="0 0 0" xyz="0.0001 -0.0513 -0.208"/>
      <mass value="1.765"/>
      <inertia ixx="0.013479" ixy="-3e-06" ixz="-3.8e-05" iyy="0.01325" iyz="0.001623" izz="0.002229"/>
    </inertial>
  </link>
  <!-- Thigh joint -->
  <joint name="RH_HFE" type="revolute">
    <parent link="RH_HIP"/>
    <child link="RH_THIGH"/>
    <origin xyz="-0.0635                    -0.041                    0.0"/>
    <axis xyz="0 1 0"/>
    <limit effort="80" lower="-6.28" upper="6.28" velocity="15"/>
    <dynamics damping="0.0" friction="0.0"/>
  </joint>
  <!-- Xacro:Properties -->
  <!-- [m] -->
  <!-- [Nm] -->
  <link name="RH_SHANK">
    <visual>
      <origin rpy="0 0 -3.14159265359" xyz="0 0 0"/>
      <geometry>
        <mesh filename="./shank/3_0/anymal_shank_l.dae" scale="0.001 0.001     0.001"/>
      </geometry>
      <material name="anymal_material"/>
    </visual>
    <collision>
      <origin rpy="0 1.57079632679 0" xyz="-0.065 0.015 0.01"/>
      <geometry>
        <box size="0.08 0.07 0.13"/>
      </geometry>
    </collision>
    <inertial>
      <origin rpy="0 0 0" xyz="-0.029 0.004 0.001"/>
      <mass value="0.21"/>
      <inertia ixx="0.0037693717909" ixy="-7.7334500762e-05" ixz="0.000152069372983" iyy="0.00400446467635" iyz="0.0003218356083" izz="0.000418471691904"/>
    </inertial>
  </link>
  <!-- Shank joint -->
  <joint name="RH_KFE" type="revolute">
    <parent link="RH_THIGH"/>
    <child link="RH_SHANK"/>
    <origin xyz="-0.0 -0.109 -0.25"/>
    <axis xyz="0 1 0"/>
    <limit effort="80" lower="-6.28" upper="6.28" velocity="15"/>
    <dynamics damping="0.0" friction="0.0"/>
  </joint>
  <!-- Xacro:Properties -->
  <!-- [m] -->
  <!-- Foot adapter link -->
  <link name="RH_ADAPTER">
    <visual>
      <origin rpy="0 0 -3.14159265359" xyz="0 0 0"/>
      <geometry>
        <mesh filename="./adapter/3_0/anymal_adapter.dae" scale="0.001 0.001     0.001"/>
      </geometry>
      <material name="anymal_material"/>
    </visual>
    <collision>
      <origin rpy="0 0 0" xyz="0 0 -0.114"/>
      <geometry>
        <cylinder length="-0.228" radius="0.015"/>
      </geometry>
    </collision>
    <inertial>
      <origin rpy="0 0 0" xyz="-0.0 -0.0036 -0.18036"/>
      <mass value="0.261"/>
      <inertia ixx="0.002983" ixy="3e-08" ixz="3.2e-07" iyy="0.00298" iyz="7e-05" izz="8.4e-05"/>
    </inertial>
  </link>
  <!-- Foot adapter joint ankle -->
  <joint name="RH_ADAPTER_JOINT" type="fixed">
    <parent link="RH_SHANK"/>
    <child link="RH_ADAPTER"/>
    <origin rpy="-0.0 -0.0 0.0" xyz="-0.1 0.02 0.0"/>
  </joint>
  <!-- Xacro:Properties -->
  <!-- [m] -->
  <link name="RH_MOUNT">
    <inertial>
      <mass value="0.0001"/>
      <inertia ixx="0.0" ixy="0.0" ixz="0.0" iyy="0.0" iyz="0.0" izz="0.0"/>
    </inertial>
    </link>
  <!-- Foot adapter joint ankle -->
  <joint name="RH_MOUNT_JOINT" type="fixed">
    <parent link="RH_ADAPTER"/>
    <child link="RH_MOUNT"/>
    <origin rpy="-0.226893 -0.0 -0.0" xyz="-0.0 -0.0 -0.228"/>
  </joint>
  <!-- Foot link -->
  <link name="RH_FOOT">
    <visual>
      <origin rpy="0 0 -3.14159265359" xyz="0 0 0.0519"/>
      <geometry>
        <mesh filename="./foot/8_0/anymal_foot_l.dae" scale="0.001 0.001     0.001"/>
      </geometry>
      <material name="anymal_material"/>
    </visual>
    <collision>
      <origin xyz="0 0 0.017275"/>
      <geometry>
        <sphere radius="0.034625"/>
      </geometry>
    </collision>
    <inertial>
      <mass value="0.0001"/>
      <inertia ixx="0.0" ixy="0.0" ixz="0.0" iyy="0.0" iyz="0.0" izz="0.0"/>
    </inertial>
  </link>
  <!-- Gazebo customization -->
  <gazebo reference="RH_FOOT">
    <kp>1000000.0</kp>
    <kd>100.0</kd>
    <mu1>0.8</mu1>
    <mu2>0.8</mu2>
  </gazebo>
  <!-- Foot joint -->
  <joint name="RH_MOUNT_TO_FOOT" type="fixed">
    <parent link="RH_MOUNT"/>
    <child link="RH_FOOT"/>
    <origin rpy="-0.0 -0.0 -0.0" xyz="0.0 0.0 -0.0519"/>
    <material name="anymal_material"/>
  </joint>
  <link name="imu_link">
    <visual>
      <origin rpy="0 0 0" xyz="0 0 0.011"/>
      <geometry>
        <box size="0.058 0.058 0.022"/>
      </geometry>
      <material name="orange"/>
    </visual>
    <collision>
      <origin rpy="0 0 0" xyz="0 0 0.011"/>
      <geometry>
        <box size="0.058 0.058 0.022"/>
      </geometry>
    </collision>
    <inertial>
      <mass value="0.05"/>
      <origin xyz="0 0 0"/>
      <inertia ixx="1.60333333333e-05" ixy="0.0" ixz="0.0" iyy="2.80333333333e-05" iyz="0.0" izz="1.60333333333e-05"/>
    </inertial>
  </link>
  <joint name="imu_joint" type="fixed">
    <parent link="base"/>
    <child link="imu_link"/>
    <origin rpy="3.14159265359 0 0" xyz="0.0245 -0.04255 0.1857"/>
  </joint>
</robot>

