<?xml version="1.0" ?>
<robot name="plane">
  <link name="chassis">
  <contact>
      <lateral_friction value="1"/>
  </contact>
    <inertial>
      <origin rpy="0 0 0" xyz="0 0.03 0.043794"/>
       <mass value="13.715"/>
       <inertia ixx="0" ixy="0" ixz="0" iyy="0" iyz="0" izz="0"/>
    </inertial>
    <visual>
      <origin rpy="0 0 0" xyz="0 0 0.043794"/>
      <geometry>
      	
				<mesh filename="chassis.stl" scale="1 1 1"/>
      </geometry>
       <material name="yellow">
        <color rgba="0.95 0.75 0.05 1"/>
      </material>
    </visual>
    <collision>
      <origin rpy="-1.57 0 0" xyz="0 0 0.043794"/>
      <geometry>
      	
				<mesh filename="chassis_vhacd_mod.obj" scale="1 1 1"/>
      </geometry>
    </collision>
  </link>
  
 
	
	 <link name="FR_hip_motor">
  <contact>
      <lateral_friction value="1"/>
  </contact>
    <inertial>
       <origin rpy="0 0 0" xyz="0.02 0 0"/>
       <mass value="0.241"/>
       <inertia ixx="0" ixy="0" ixz="0" iyy="0" iyz="0" izz="0"/>
    </inertial>
	
	  <visual>
      <origin rpy="0 0 0" xyz="0 0 0"/>
      <geometry>
				<mesh filename="hip_motor_mirror.stl" scale="1 1 1"/>
      </geometry>
       <material name="green"/>
    </visual>
    
    <collision>
      <origin rpy="0 0 0" xyz="0 0 0"/>
      <geometry>
				<mesh filename="hip_motor_mirror.stl" scale="1 1 1"/>
      </geometry>
    </collision>
    </link>
    
    <joint name="FR_hip_motor_2_chassis_joint" type="continuous">
		<axis xyz="0 0 -1"/>
		<parent link="chassis"/>
		<child link="FR_hip_motor"/>
		<origin rpy="0 0 0" xyz="-0.0817145 0 0.242889"/>
		<limit effort="100" velocity="100"/>
		<joint_properties damping=".0" friction=".0"/>
	</joint>
	
     <link name="FR_upper_leg">
  <contact>
      <lateral_friction value="1"/>
  </contact>
    <inertial>
     <origin rpy="0 0 0" xyz="0 -0.04 -0.04"/>
       <mass value="1.527"/>
       <inertia ixx="0" ixy="0" ixz="0" iyy="0" iyz="0" izz="0"/>
    </inertial>
       <visual>
      <origin rpy="0 0 0" xyz="0 0 0"/>
      <geometry>
				<mesh filename="upper_leg_mirror.stl" scale="1 1 1"/>
      </geometry>
       <material name="blue"/>
    </visual>
    
    <collision>
      <origin rpy="0 0 0" xyz="0 0 0"/>
      <geometry>
				<mesh filename="upper_leg_right_vhacd.obj" scale="1 1 1"/>
      </geometry>
    </collision>
    
    </link>
    
    <joint name="FR_upper_leg_2_hip_motor_joint" type="continuous">
		<axis xyz="1 0 0"/>
		<parent link="FR_hip_motor"/>
		<child link="FR_upper_leg"/>
		<origin rpy="0 0 0" xyz="-0.053565 0 0"/>
		<limit effort="100" velocity="100"/>
		<joint_properties damping=".0" friction=".0"/>
	</joint>
    </robot>	
